Workbook

Sheet Registo_Feiras
A1: PROJECTO FAZER PROSPERAR — FICHA DE MONITORIA: FEIRA COMUNITÁRIA E NETWORKING
A2: Uma linha por produto por participante · Preencher no dia da feira · Fonte: indicadores A4-01 · OUT1-01 · OUT3-01
A3: Nº | B3: Data da Feira | C3: Distrito | D3: Local da Feira | E3: Responsável (Facilitador/a) | F3: ID Participante | G3: Nome do/a Participante | H3: Sexo | I3: Comunidade / Localidade | J3: Categoria do Produto | K3: Produto (descrição) | L3: Qtd. Inicial (Kg / Un.) | M3: Qtd. Vendida (Kg / Un.) | N3: Qtd. Não Vendida [auto] | O3: % Vendido [auto] | P3: Preço / Un. (MZN) | Q3: Valor Total Vendido (MZN) [auto] | R3: Estabeleceu novos contactos / ligações de mercado? (OUT3-01) | S3: Evidência de aplicação de habilidades no negócio? (OUT1-01) | T3: Observações / Descrição das novas oportunidades
A4: 1 | B4: 30/06/2026 | C4: Nacala-a-Porto | D4: Praça da independencia | E4: Belo Simao Tiago | F4: PRJ_0015 | G4: Maria Adamo | H4: Feminino | I4: Murrupelane | J4: Alim. não perecível (revenda) | K4: Cana de acucar | L4: 15 | M4: 10 | N4: 5 | O4: 0.67 | P4: 10 | Q4: =M4*P4 -> 100 | R4: Sim | S4: Sim — negócio em funcionamento
A5: 2 | B5: 30/06/2026 | C5: Nacala-a-Porto | D5: Praça da independencia | E5: Belo Simao Tiago | F5: PRJ_0030 | G5: Neusa Gregorio Muireque | H5: Feminino | I5: Mocone | J5: Alim. perecível (revenda) | K5: Laranja | L5: 28 | M5: 10 | N5: 18 | O5: 0.36 | P5: 5 | Q5: =M5*P5 -> 50 | R5: Sim | S5: Sim — negócio em funcionamento
A6: 3 | B6: 30/06/2026 | C6: Nacala-a-Porto | D6: Praça da independencia | E6: Belo Simao Tiago | F6: PRJ_0030 | G6: Neusa Gregorio | H6: Feminino | I6: Mocone | J6: Alim. perecível (revenda) | K6: Banana | L6: 16 | M6: 10 | N6: 6 | O6: 0.63 | P6: 5 | Q6: =M6*P6 -> 50 | R6: Sim | S6: Sim — negócio em funcionamento
A7: 4 | B7: 30/06/2026 | C7: Nacala-a-Porto | D7: Praça da independencia | E7: Belo Simao Tiago | F7: PRJ_0177 | G7: Rassul Bacar Firmino | H7: Masculino | I7: Murrupelane | J7: Vestuário | K7: Saias de capulana | L7: 4 | M7: 1 | N7: 3 | O7: 0.25 | P7: 50 | Q7: =M7*P7 -> 50 | R7: Sim | S7: Sim — novo produto/serviço
A8: 5 | B8: 30/06/2026 | C8: Nacala-a-Porto | D8: Praça da independencia | E8: Belo Simao Tiago | F8: PRJ_0270 | G8: Alfredo Pedro Vantilia | H8: Masculino | I8: Murrupelane | J8: Higiene e limpeza | K8: Omo | L8: 42 | M8: 7 | N8: 35 | O8: 0.17 | P8: 5 | Q8: =M8*P8 -> 35 | R8: Sim | S8: Sim — negócio em funcionamento
A9: 6 | B9: 30/06/2026 | C9: Nacala-a-Porto | D9: Praça da independencia | E9: Belo Simao Tiago | F9: PRJ_0270 | G9: Alfredo Pedro Vantilia | H9: Masculino | I9: Murrupelane | J9: Outro | K9: Gelinho | L9: 100 | M9: 10 | N9: 90 | O9: 0.1 | P9: 1 | Q9: =M9*P9 -> 10 | R9: Sim | S9: Sim — novo produto/serviço
A10: 7 | B10: 30/06/2026 | C10: Nacala-a-Porto | D10: Praça da independencia | E10: Belo Simao Tiago | F10: PRJ_0270 | G10: Alfredo Pedro Vantilia | H10: Masculino | I10: Murrupelane | J10: Outro | K10: Fralda descartavel | L10: 10 | M10: 2 | N10: 8 | O10: 0.2 | P10: 10 | Q10: =M10*P10 -> 20 | R10: Sim | S10: Sim — negócio em funcionamento
A11: 8 | B11: 30/06/2026 | C11: Nacala-a-Porto | D11: Praça da independencia | E11: Belo Simao Tiago | F11: PRJ_0322 | G11: Salima Rafael Armando Joao | H11: Feminino | I11: Murrupelane | J11: Alim. confeccionado/preparado | K11: Bolinhos | L11: 200 | M11: 10 | N11: 190 | O11: 0.05 | P11: 5 | Q11: =M11*P11 -> 50 | R11: Sim | S11: Sim — negócio em funcionamento
A12: 9 | B12: 30/06/2026 | C12: Nacala-a-Porto | D12: Praça da independencia | E12: Belo Simao Tiago | F12: PRJ_0322 | G12: Salima Rafael Armando Joao | H12: Feminino | I12: Murrupelane | J12: Alim. confeccionado/preparado | K12: Maheu | L12: 3 | M12: 3 | N12: 0 | O12: 1 | P12: 10 | Q12: =M12*P12 -> 30 | R12: Sim | S12: Sim — negócio em funcionamento
A13: 10 | B13: 30/06/2026 | C13: Nacala-a-Porto | D13: Praça da independencia | E13: Belo Simao Tiago | F13: PRJ_0025 | G13: Amelia Afonso Momade | H13: Feminino | I13: Mocone | J13: Alim. não perecível (revenda) | K13: Massa esparguete | L13: 12 | M13: 3 | N13: 9 | O13: 0.25 | P13: 25 | Q13: =M13*P13 -> 75 | R13: Sim | S13: Sim — negócio em funcionamento
A14: 11 | B14: 30/06/2026 | C14: Nacala-a-Porto | D14: Praça da independencia | E14: Belo Simao Tiago | F14: PRJ_0025 | G14: Amelia Afonso Momade | H14: Feminino | I14: Mocone | J14: Alim. não perecível (revenda) | K14: Nick nack | L14: 50 | M14: 5 | N14: 45 | O14: 0.1 | P14: 5 | Q14: =M14*P14 -> 25 | R14: Sim | S14: Sim — negócio em funcionamento
A15: 12 | B15: 30/06/2026 | C15: Nacala-a-Porto | D15: Praça da independencia | E15: Belo Simao Tiago | F15: PRJ_0025 | G15: Amelia Afonso Momade | H15: Feminino | I15: Mocone | J15: Alim. não perecível (revenda) | K15: Doces | L15: 30 | M15: 5 | N15: 25 | O15: 0.17 | P15: 5 | Q15: =M15*P15 -> 25 | R15: Sim | S15: Sim — negócio em funcionamento
A16: 13 | B16: 30/06/2026 | C16: Nacala-a-Porto | D16: Praça da independencia | E16: Belo Simao Tiago | F16: PRJ_0025 | G16: Amelia Afonso Momade | H16: Feminino | I16: Mocone | J16: Alim. não perecível (revenda) | K16: Caldo | L16: 30 | M16: 2 | N16: 28 | O16: 0.07 | P16: 6 | Q16: =M16*P16 -> 12 | R16: Sim | S16: Sim — negócio em funcionamento
A17: 1 | B17: 30/06/2026 | C17: Nacala-a-Porto | D17: Praça dos Heróis | E17: Magrofate Justino | F17: PRJ_0053 | G17: Fatima Henriques Mascate | H17: Feminino | I17: Mathápue | J17: Alim. perecível (revenda) | K17: Banana madura | L17: 20 | M17: 17 | N17: 3 | O17: 0.85 | P17: 5 | Q17: =M17*P17 -> 85 | R17: Sim | S17: Sim — novo produto/serviço | T17: Era a sua primeira vez a vender só tinha como ideias do seu plano de Negócios como adicional.
A18: 2 | B18: 30/06/2026 | C18: Nacala-a-Porto | D18: Praça dos Heróis | E18: Magrofate Justino | F18: PRJ_0053 | G18: Fatima Henriques Mascate | H18: Feminino | I18: Mathápue | J18: Alim. perecível (revenda) | K18: Laranjas | L18: 21 | M18: 14 | N18: 7 | O18: 0.67 | P18: 5 | Q18: =M18*P18 -> 70 | R18: Sim | S18: Sim — novo produto/serviço | T18: Igualmente era sua primeira experiência a vender mas tinha como ideia adicional .
A19: 3 | B19: 30/06/2026 | C19: Nacala-a-Porto | D19: Praça dos Heróis | E19: Magrofate Justino | F19: PRJ_0053 | G19: Fatima Henriques Mascate | H19: Feminino | I19: Mathápue | J19: Outro | K19: Carteira móvel (e-mola) | L19: 2 | M19: 11 | N19: -9 | O19: 5.5 | P19: 50 | Q19: =M19*P19 -> 550 | R19: Sim | S19: Sim — negócio em funcionamento | T19: Era o negocio que fazia desde o início sas mentorias.
A20: 4 | B20: 30/06/2026 | C20: Nacala-a-Porto | D20: Praça dos Heróis | E20: Magrofate Justino | F20: PRJ_220 | G20: Paulo Guilherme | H20: Masculino | I20: Mocone | J20: Alim. não perecível (revenda) | K20: Bolachas | L20: 23 | M20: 2 | N20: 21 | O20: 0.09 | P20: 10 | Q20: =M20*P20 -> 20 | R20: Sim | S20: Sim — negócio em funcionamento | T20: Vendeu e idententicou nova loja fornecedora e a preços acessicel
A21: 5 | B21: 30/06/2026 | C21: Nacala-a-Porto | D21: Praça dos Heróis | E21: Magrofate Justino | F21: PRJ_0220 | G21: Paulo Guilherme | H21: Masculino | I21: Mocone | J21: Alim. não perecível (revenda) | K21: caldos | L21: 44 | M21: 6 | N21: 38 | O21: 0.14 | P21: 6 | Q21: =M21*P21 -> 36 | R21: Sim | S21: Sim — negócio em funcionamento | T21: troca de contactos entre colegas que expunha.
A22: 6 | B22: 30/06/2026 | C22: Nacala-a-Porto | D22: Praça dos Heróis | E22: Magrofate Justino | F22: PRJ_0220 | G22: Paulo Guilherme | H22: Masculino | I22: Mocone | J22: Alim. não perecível (revenda) | K22: doces | L22: 104 | M22: 15 | N22: 89 | O22: 0.14 | P22: 1 | Q22: =M22*P22 -> 15 | R22: Sim | S22: Sim — negócio em funcionamento | T22: vendeu mas sai mais em casa, disse.
A23: 7 | B23: 30/06/2026 | C23: Nacala-a-Porto | D23: Praça dos Heróis | E23: Magrofate Justino | F23: PRJ_0220 | G23: Paulo Guilherme | H23: Masculino | I23: Mocone | J23: Higiene e limpeza | K23: Fraldas (descartaveis) | L23: 10 | M23: 0 | N23: 10 | O23: 0 | P23: 5 | Q23: =M23*P23 -> 0 | R23: Não | S23: Não | T23: Nao chegou de vender sequer algum.
A24: 8 | B24: 30/06/2026 | C24: Nacala-a-Porto | D24: Praça dos Heróis | E24: Magrofate Justino | F24: PRJ_0061 | G24: Anchita Abdala | H24: Feminino | I24: Mocone | J24: Alim. perecível (revenda) | K24: Laranjas | L24: 30 | M24: 12 | N24: 18 | O24: 0.4 | P24: 5 | Q24: =M24*P24 -> 60 | R24: Sim | S24: Sim — negócio em funcionamento | T24: Em progresso
A25: 9 | B25: 30/06/2026 | C25: Nacala-a-Porto | D25: Praça dos Heróis | E25: Magrofate Justino | F25: PRJ_0061 | G25: Anchita Abdala | H25: Feminino | I25: Mocone | J25: Alim. perecível (revenda) | K25: Bananas | L25: 36 | M25: 17 | N25: 19 | O25: 0.47 | P25: 5 | Q25: =M25*P25 -> 85 | R25: Sim | S25: Sim — negócio em funcionamento | T25: Em progresso
A26: 10 | B26: 30/06/2026 | C26: Nacala-a-Porto | D26: Praça dos Heróis | E26: Magrofate Justino | F26: PRJ_0061 | G26: Anchita Abdala | H26: Feminino | I26: Mocone | J26: Alim. perecível (revenda) | K26: Tangerinas | L26: 20 | M26: 18 | N26: 2 | O26: 0.9 | P26: 5 | Q26: =M26*P26 -> 90 | R26: Sim | S26: Sim — negócio em funcionamento
A27: 1 | B27: 30/06/2026 | C27: Nacala-a-Porto | D27: Praça dos heróis | E27: Vanil Horácio | F27: PRJ_0236 | G27: Jordania Jorge João | H27: Feminino | I27: Triângulo | J27: Alimentício | K27: Arroz e feijão cuzido | L27: 9 | M27: 9 | N27: 0 | O27: 1 | P27: 50 | Q27: =M27*P27 -> 450 | R27: Sim | S27: Sim — negócio em funcionamento | T27: A participante conseguiu adquirir certas informações referentes a tratamento de NUIT a mesma pretende usar para abrir uma conta bancaria para quansar seu dinheiro.
A28: 2 | B28: 30/06/2026 | C28: Nacala-a-Porto | D28: Praça dos herois | E28: Vanil Horácio | F28: PRJ_0236 | G28: Jordania Jorge João | H28: Feminino | I28: Triângulo | J28: Alimentício | K28: Arroz feição e frango | L28: 3 | M28: 3 | N28: 0 | O28: 1 | P28: 90 | Q28: =M28*P28 -> 270 | R28: sim | S28: Sim — negócio em funcionamento
A29: 3 | B29: 30/06/2026 | C29: Nacala-a-Porto | D29: Praça dos heróis | E29: Vanil Horácio | F29: PRJ_0191 | G29: Mique Abdala | H29: Masculino | I29: Triângulo | J29: Calçados | K29: Sapatos | L29: 3 | M29: 1 | N29: 2 | O29: 0.33 | P29: 350 | Q29: =M29*P29 -> 350 | R29: Sim | S29: Sim — negócio em funcionamento | T29: O participante teve uma atenção especial do administrador do distrito referente ao negócio que ele esta a fazer, foi questionado sobre o loxal de levantamento dos seus produtos, e ele respodeu que faz o levantamento anivel da urbe da cidade, o administrador sugerio ao participantes para comcorer ao FDEL.
A30: 4 | B30: 30/06/2026 | C30: Nacala-a-Porto | D30: Praça dos heróis | E30: Vanil Horácio | F30: PRJ_0191 | G30: Mique Abdala | H30: Masculino | I30: Triângulo | J30: Vestuário | K30: Camisa | L30: 6 | M30: 1 | N30: 5 | O30: 0.17 | P30: 150 | Q30: =M30*P30 -> 150 | R30: Sim | S30: Sim — negócio em funcionamento
A31: 5 | B31: 30/06/2026 | C31: Nacala-a-Porto | D31: Praça dos heróis | E31: Vanil Horácio | F31: PRJ_0106 | G31: Fina Sualehe | H31: Feminino | I31: Triângulo | J31: Alimentício | K31: feijão | L31: 10 | M31: 3 | N31: 0 | O31: 0.3 | P31: 65 | Q31: =M31*P31 -> 195 | R31: Não | S31: Sim — negócio em funcionamento
A32: 6 | B32: 30/06/2026 | C32: Nacala-a-Porto | D32: Praça dos heróis | E32: Vanil Horácio | F32: PRJ_0154 | G32: Amade Trage Ibraimo | H32: Masculino | I32: Triângulo | J32: Alimentício | K32: Doces de coco e açúcar | L32: 200 | M32: 47 | N32: 153 | O32: 0.24 | P32: 5 | Q32: =M32*P32 -> 235 | R32: Sim | S32: Sim — negócio em funcionamento | T32: O participante conseguio tratar o seu NUIT, conseguio registar um novo cartão com o seu próprio nome para abrir uma conta movel, antigamente ele usava cartão do seu tio.
A33: 1 | B33: 30/06/2026 | C33: Nacala-a-Porto | D33: Praça dos heróis | E33: Nuchate Chico Estevão | F33: PRJ_0333 | G33: Celestina José | H33: Feminino | I33: Naherenque | J33: Alim. confeccionado/preparado | K33: Feijão Fava | L33: 36 | M33: 21 | N33: 4 | O33: =IFERROR(M33/L33,"") -> 0.58333333 | P33: 5 | Q33: =M33*P33 -> 105 | R33: Não | T33: A PARTICIPANTE CONSEGUIU REGISTAR A SI E SEU FILHO
A34: 2 | B34: 30/06/2026 | C34: Nacala-a-Porto | D34: Praça dos heróis | E34: Nuchate Chico Estevão | F34: PRJ_0307 | G34: Juma Amisse | H34: Masculino | I34: Naherenque | J34: Alim. não perecível (revenda) | K34: Amendoim seco | L34: 30 | M34: 8 | N34: =IFERROR(L34-M34,"") -> 22 | O34: =IFERROR(M34/L34,"") -> 0.26666667 | P34: 20 | Q34: =M34*P34 -> 160 | R34: Não
A35: 3 | B35: 30/06/2026 | C35: Nacala-a-Porto | D35: Praça dos heróis | E35: Nuchate Chico Estevão | F35: PRJ_0076 | G35: Rabia Almasse | H35: Feminino | I35: Naherenque | J35: Alim. perecível (revenda) | K35: Banana | L35: 40 | M35: 17 | N35: =IFERROR(L35-M35,"") -> 23 | O35: =IFERROR(M35/L35,"") -> 0.425 | P35: 5 | Q35: =M35*P35 -> 85 | R35: Não
A36: 4 | B36: 30/06/2026 | C36: Nacala-a-Porto | D36: Praça dos heróis | E36: Nuchate Chico Estevão | F36: PRJ_0076 | G36: Rabia Almasse | H36: Feminino | I36: Naherenque | J36: Alim. perecível (revenda) | K36: Laranja | L36: 10 | M36: 4 | N36: =IFERROR(L36-M36,"") -> 6 | O36: =IFERROR(M36/L36,"") -> 0.4 | P36: 5 | Q36: =M36*P36 -> 20 | R36: Não
A37: 5 | B37: 30/06/2026 | C37: Nacala-a-Porto | D37: Praça dos heróis | E37: Nuchate Chico Estevão | F37: PRJ_0336 | G37: Fenísia Júlia Júlio | H37: Feminino | I37: Ontupaia | J37: Alim. confeccionado/preparado | K37: Bolinhos fritos | L37: 30 | M37: 17 | N37: =IFERROR(L37-M37,"") -> 13 | O37: =IFERROR(M37/L37,"") -> 0.56666667 | P37: 5 | Q37: =M37*P37 -> 85 | R37: Não
A38: 6 | B38: 30/06/2026 | C38: Nacala-a-Porto | D38: Praça dos heróis | E38: Nuchate Chico Estevão | F38: PRJ_0280 | G38: Momade Saide | H38: Masculino | I38: Ontupaia | J38: Vestuário | K38: Vestidos para criança | L38: 3 | M38: 1 | N38: =IFERROR(L38-M38,"") -> 2 | O38: =IFERROR(M38/L38,"") -> 0.33333333 | P38: 70 | Q38: =M38*P38 -> 70 | R38: Não
A39: 7 | B39: 30/06/2026 | C39: Nacala-a-Porto | D39: Praça dos heróis | E39: Nuchate Chico Estevão | F39: PRJ_0280 | G39: Momade Saide | H39: Masculino | I39: Ontupaia | J39: Vestuário | K39: Vestidos para adulto | L39: 5 | M39: 2 | N39: =IFERROR(L39-M39,"") -> 3 | O39: =IFERROR(M39/L39,"") -> 0.4 | P39: 100 | Q39: =M39*P39 -> 200 | R39: Não
A40: 8 | B40: 30/06/2026 | C40: Nacala-a-Porto | D40: Praça dos heróis | E40: Nuchate Chico Estevão | F40: PRJ_0280 | G40: Momade Saide | H40: Masculino | I40: Ontupaia | J40: Vestuário | K40: Saia para criança | L40: 1 | M40: 0 | N40: =IFERROR(L40-M40,"") -> 1 | O40: =IFERROR(M40/L40,"") -> 0 | P40: 50 | Q40: =M40*P40 -> 0 | R40: Não
...

Sheet Resumo_Feira
A1: PROJECTO FAZER PROSPERAR — RESUMO DA FEIRA COMUNITÁRIA
A2: Calculado automaticamente a partir de Registo_Feiras · Contribui para indicadores A4-01 · OUT1-01 · OUT3-01
A5: CONTRIBUIÇÃO PARA OS INDICADORES TOC — FAZER PROSPERAR
A6: Código | B6: Indicador TOC | C6: Nível TOC | D6: Como esta ficha contribui | E6: Valor calculado | F6: Meta | G6: Nota
A7: A4-01 | B7: 1 feira comunitária e evento de networking organizado | C7: Actividade | D7: Indica se a feira foi realizada: ✅ se existem registos de participantes, ⏳ se ainda não há registo. Número de participantes disponível na linha 14 do resumo. | E7: =IF(COUNTA(Registo_Feiras!F4:F303)>0,"✅ Realizada","⏳ Não registada") -> ✅ Realizada | F7: 1 evento / 350 part. | G7: Confirmar com relatório administrativo do evento
A8: OUT1-01 | B8: 50% dos participantes aplicam habilidades em actividades de geração de renda | C8: Outcome 1 | D8: % de participantes com evidência de aplicação de habilidades no negócio (col. S = 'Sim') | E8: =IFERROR((COUNTIF(Registo_Feiras!S4:S303,"Sim — negócio em funcionamento")+COUNTIF(Registo_Feiras!S4:S303,"Sim — novo produto/serviço"))/COUNTA(Registo_Feiras!F4:F303),"") -> 0.80357143 | F8: 50% (175 part.) | G8: Triangular com Ficha de Mentoria (estado do negócio) e Voz do Participante
A9: OUT3-01 | B9: 30% reinvestem rendimentos no negócio ou em oportunidades produtivas | C9: Outcome 3 | D9: % de participantes que estabeleceram novas ligações de mercado na feira (col. R = 'Sim') | E9: =IFERROR(COUNTIF(Registo_Feiras!R4:R303,"Sim")/COUNTA(Registo_Feiras!F4:F303),"") -> 0.625 | F9: 30% (105 part.) | G9: Proxy de reinvestimento — triangular com Ficha de Mentoria (stock e códigos DIV/GEST)
A11: TOTAIS GERAIS
A12: Indicador operacional | B12: Resultado | C12: Nota
A13: Total de linhas preenchidas (registos produto × participante) | B13: =COUNTA(Registo_Feiras!F4:F303) -> 56
A14: Total de participantes únicos na feira | B14: =SUMPRODUCT((Registo_Feiras!F4:F303<>"")/IF(COUNTIF(Registo_Feiras!F4:F303,Registo_Feiras!F4:F303)>0,COUNTIF(Registo_Feiras!F4:F303,Registo_Feiras!F4:F303),1)) -> 14 | C14: Conta ID únicos
A15: Participantes do sexo feminino | B15: =COUNTIF(Registo_Feiras!H4:H303,"Feminino") -> 40
A16: Participantes do sexo masculino | B16: =COUNTIF(Registo_Feiras!H4:H303,"Masculino") -> 16
A17: Valor total vendido na feira (MZN) | B17: =IFERROR(SUM(Registo_Feiras!Q4:Q303),0) -> 5943
A18: Quantidade total vendida (todas as categorias) | B18: =IFERROR(SUM(Registo_Feiras!M4:M303),0) -> 564
A19: % média de produto vendido por participante | B19: =IFERROR(AVERAGEIF(Registo_Feiras!O4:O303,">"&0),"") -> 0.54462185 | C19: Média da coluna % Vendido
A20: Participantes com novas ligações de mercado (OUT3-01) | B20: =COUNTIF(Registo_Feiras!R4:R303,"Sim") -> 35 | C20: Contribui para OUT3-01
A21: Participantes com evidência de aplicação de habilidades (OUT1-01) | B21: =COUNTIF(Registo_Feiras!S4:S303,"Sim — negócio em funcionamento")+COUNTIF(Registo_Feiras!S4:S303,"Sim — novo produto/serviço") -> 45 | C21: Contribui para OUT1-01
A23: LEGENDA: 🟡 OUT1-01 = Outcome 1 (Inclusão Económica — aplicação de habilidades) 🟠 OUT3-01 = Outcome 3 (Reinvestimento — novas ligações de mercado) 🔵 A4-01 = Actividade 4 (realização da feira)
